<mujoco model="MOZ1">
  <default>
    <default class="robot">
      <default class="motor">
        <!-- urdf2mjcf 会删掉根连杆 inertial；已在 base_link 手动补回。无 ctrl 时用弹簧保持零位 -->
        <joint damping="0.4" armature="0.1" stiffness="8000" />
        <motor />
      </default>
      <default class="visual">
        <geom material="visualgeom" contype="0" conaffinity="0" group="2" />
      </default>
      <default class="collision">
        <geom material="collision_material" condim="3" contype="0" conaffinity="1" priority="1" group="1" solref="0.005 1" solimp="0.99 0.999 1e-05" friction="1 0.01 0.01" />
      </default>
    </default>
  </default>

  <compiler angle="radian" />

  <option timestep="0.002" gravity="0 0 -9.81" integrator="implicitfast" />

  <asset>
    <material name="urdf_visual" rgba="0.8 0.8 0.8 1.0" />
    <material name="visualgeom" rgba="0.8 0.8 0.8 1" />
    <material name="dark_grey" rgba="0.3 0.3 0.3 1.0" />
    <material name="default_material" rgba="0.7 0.7 0.7 1" />
    <material name="collision_material" rgba="1.0 0.28 0.1 0" />
    <mesh name="base_link.STL" file="../meshes/base_link.STL" />
    <mesh name="wheel.STL" file="../meshes/wheel.STL" />
    <mesh name="leg01.STL" file="../meshes/leg01.STL" />
    <mesh name="leg02.STL" file="../meshes/leg02.STL" />
    <mesh name="leg03.STL" file="../meshes/leg03.STL" />
    <mesh name="waist01.STL" file="../meshes/waist01.STL" />
    <mesh name="waist02.STL" file="../meshes/waist02.STL" />
    <mesh name="waist03.STL" file="../meshes/waist03.STL" />
    <mesh name="left01.STL" file="../meshes/left01.STL" />
    <mesh name="left02.STL" file="../meshes/left02.STL" />
    <mesh name="left03.STL" file="../meshes/left03.STL" />
    <mesh name="left04.STL" file="../meshes/left04.STL" />
    <mesh name="left05.STL" file="../meshes/left05.STL" />
    <mesh name="left06.STL" file="../meshes/left06.STL" />
    <mesh name="left07.STL" file="../meshes/left07.STL" />
    <mesh name="right01.STL" file="../meshes/right01.STL" />
    <mesh name="right02.STL" file="../meshes/right02.STL" />
    <mesh name="right03.STL" file="../meshes/right03.STL" />
    <mesh name="right04.STL" file="../meshes/right04.STL" />
    <mesh name="right05.STL" file="../meshes/right05.STL" />
    <mesh name="right06.STL" file="../meshes/right06.STL" />
    <mesh name="right07.STL" file="../meshes/right07.STL" />
    <mesh name="head21.STL" file="../meshes/head21.STL" />
    <mesh name="head22.STL" file="../meshes/head22.STL" />
    <mesh name="head23.STL" file="../meshes/head23.STL" />
  </asset>

  <worldbody>
    <light name="sun" diffuse="0.85 0.85 0.85" specular="0.4 0.4 0.4" pos="0 0 5" dir="0 0 -1" />
    <geom name="floor" type="plane" size="50 50 0.01" pos="0 0 0" rgba="0.92 0.92 0.92 1" contype="1" conaffinity="1" />
    <body name="base_link" pos="0.00000000 0.00000000 0.00000000" quat="1 0 0 0" childclass="robot">
      <freejoint name="floating_base" />
      <inertial pos="0.00718 0.03634 0.03333" quat="1 0 0 0" mass="60.64" diaginertia="1.86830738 1.63486351 2.82299198" />
      <geom name="base_link_collision" pos="0 0 0" quat="1.0 0.0 0.0 0.0" type="mesh" mesh="base_link.STL" class="collision" />
      <geom name="base_link_visual" pos="0 0 0" quat="1.0 0.0 0.0 0.0" material="urdf_visual" type="mesh" mesh="base_link.STL" class="visual" />
      <body name="wheel01" pos="0.2423 0.2423 0" quat="0.38268343245394154 0.0 0.0 0.9238795324744832">
        <joint name="Base-0" type="hinge" ref="0.0" class="motor" axis="0 1 0" />
        <inertial pos="-2.82894788428134E-08 3.64072081787681E-08 0.00740010866864477" quat="1.0 0.0 0.0 0.0" mass="2.71499215054225" diaginertia="0.0010084699711565 0.00100845854065413 0.0015780295074005" />
        <geom name="wheel01_collision" pos="0 0 0" quat="1.0 0.0 0.0 0.0" type="mesh" mesh="wheel.STL" class="collision" />
        <geom name="wheel01_visual" pos="0 0 0" quat="1.0 0.0 0.0 0.0" material="urdf_visual" type="mesh" mesh="wheel.STL" class="visual" />
      </body>
      <body name="wheel02" pos="-0.2423 0.2423 0" quat="0.38268343245394154 0.0 0.0 -0.9238795324744832">
        <joint name="Base-1" type="hinge" ref="0.0" class="motor" axis="0 1 0" />
        <inertial pos="-2.82894788428134E-08 3.64072082065237E-08 0.00740010866864449" quat="1.0 0.0 0.0 0.0" mass="2.71499215054224" diaginertia="0.00100846997115651 0.00100845854065414 0.00157802950740051" />
        <geom name="wheel02_collision" pos="0 0 0" quat="1.0 0.0 0.0 0.0" type="mesh" mesh="wheel.STL" class="collision" />
        <geom name="wheel02_visual" pos="0 0 0" quat="1.0 0.0 0.0 0.0" material="urdf_visual" type="mesh" mesh="wheel.STL" class="visual" />
      </body>
      <body name="wheel03" pos="-0.2423 -0.2423 0" quat="0.9238795325873352 0.0 0.0 -0.3826834321814926">
        <joint name="Base-2" type="hinge" ref="0.0" class="motor" axis="0 1 0" />
        <inertial pos="-2.82894793979249E-08 3.64072081926459E-08 0.00740010866864538" quat="1.0 0.0 0.0 0.0" mass="2.71499215054224" diaginertia="0.0010084699711565 0.00100845854065412 0.0015780295074005" />
        <geom name="wheel03_collision" pos="0 0 0" quat="1.0 0.0 0.0 0.0" type="mesh" mesh="wheel.STL" class="collision" />
        <geom name="wheel03_visual" pos="0 0 0" quat="1.0 0.0 0.0 0.0" material="urdf_visual" type="mesh" mesh="wheel.STL" class="visual" />
      </body>
      <body name="wheel04" pos="0.2423 -0.2423 0" quat="0.9238795325873352 0.0 0.0 0.3826834321814926">
        <joint name="Base-3" type="hinge" ref="0.0" class="motor" axis="0 1 0" />
        <inertial pos="-2.82894789260801E-08 3.64072082065237E-08 0.00740010866864449" quat="1.0 0.0 0.0 0.0" mass="2.71499215054224" diaginertia="0.00100846997115651 0.00100845854065413 0.00157802950740051" />
        <geom name="wheel04_collision" pos="0 0 0" quat="1.0 0.0 0.0 0.0" type="mesh" mesh="wheel.STL" class="collision" />
        <geom name="wheel04_visual" pos="0 0 0" quat="1.0 0.0 0.0 0.0" material="urdf_visual" type="mesh" mesh="wheel.STL" class="visual" />
      </body>
      <body name="lidar_link" pos="0 -0.2522 0.1919" quat="1.0 0.0 0.0 0.0">
        <geom name="lidar_link_collision" pos="0 0 0" quat="1.0 0.0 0.0 0.0" type="box" size="0.05 0.05 0.05" class="collision" />
        <geom name="lidar_link_visual" pos="0 0 0" quat="1.0 0.0 0.0 0.0" material="dark_grey" type="box" size="0.05 0.05 0.05" class="visual" />
      </body>
      <body name="leg01" pos="0 0.1114 0.1875" quat="1.0 0.0 0.0 0.0">
        <joint name="LegWaist-0" type="hinge" ref="0.0" class="motor" range="-0.523598776 0.523598776" axis="0 1 0" />
        <inertial pos="-0.0061703700000000005 -0.00163202 0.06844628" quat="1.0 0.0 0.0 0.0" mass="5.01910066" diaginertia="0.028062430896977783 0.028107434659770565 0.00925350712118246" />
        <geom name="leg01_collision" pos="0 0 0" quat="1.0 0.0 0.0 0.0" type="mesh" mesh="leg01.STL" class="collision" />
        <geom name="leg01_visual" pos="0 0 0" quat="1.0 0.0 0.0 0.0" material="urdf_visual" type="mesh" mesh="leg01.STL" class="visual" />
        <body name="leg02" pos="0 0 0.122" quat="1.0 0.0 0.0 0.0">
          <joint name="LegWaist-1" type="hinge" ref="0.0" class="motor" range="-1.570796327 1.570796327" axis="1 0 0" />
          <inertial pos="-0.00881747 -0.00241472 0.16017954" quat="1.0 0.0 0.0 0.0" mass="5.9319879" diaginertia="0.08923107 0.10395431 0.02756185" />
          <geom name="leg02_collision" pos="0 0 0" quat="1.0 0.0 0.0 0.0" type="mesh" mesh="leg02.STL" class="collision" />
          <geom name="leg02_visual" pos="0 0 0" quat="1.0 0.0 0.0 0.0" material="urdf_visual" type="mesh" mesh="leg02.STL" class="visual" />
          <body name="leg03" pos="0 0 0.285" quat="1.0 0.0 0.0 0.0">
            <joint name="LegWaist-2" type="hinge" ref="0.0" class="motor" range="-2.530727415 0.017453293" axis="1 0 0" />
            <inertial pos="-0.009382999999999999 -0.00063508 0.16973626" quat="1.0 0.0 0.0 0.0" mass="6.15146643" diaginertia="0.13156277307149797 0.14141280477871998 0.024235249607062838" />
            <geom name="leg03_collision" pos="0 0 0" quat="1.0 0.0 0.0 0.0" type="mesh" mesh="leg03.STL" class="collision" />
            <geom name="leg03_visual" pos="0 0 0" quat="1.0 0.0 0.0 0.0" material="urdf_visual" type="mesh" mesh="leg03.STL" class="visual" />
            <body name="waist01" pos="0 0 0.318" quat="1.0 0.0 0.0 0.0">
              <joint name="LegWaist-3" type="hinge" ref="0.0" class="motor" range="-0.174532925 1.396263402" axis="1 0 0" />
              <inertial pos="-0.0021777700000000003 0.0057512 0.06814781" quat="1.0 0.0 0.0 0.0" mass="5.02420522" diaginertia="0.029000945791350378 0.028739349709173627 0.010353219665116972" />
              <geom name="waist01_collision" pos="0 0 0" quat="1.0 0.0 0.0 0.0" type="mesh" mesh="waist01.STL" class="collision" />
              <geom name="waist01_visual" pos="0 0 0" quat="1.0 0.0 0.0 0.0" material="urdf_visual" type="mesh" mesh="waist01.STL" class="visual" />
              <body name="waist02" pos="0 0 0.12" quat="1.0 0.0 0.0 0.0">
                <joint name="LegWaist-4" type="hinge" ref="0.0" class="motor" range="-0.523598776 0.523598776" axis="0 1 0" />
                <inertial pos="0.0 0.0093749 0.07131262" quat="1.0 0.0 0.0 0.0" mass="3.22036562" diaginertia="0.021660529670841488 0.016636603579758467 0.010649176091083021" />
                <geom name="waist02_collision" pos="0 0 0" quat="1.0 0.0 0.0 0.0" type="mesh" mesh="waist02.STL" class="collision" />
                <geom name="waist02_visual" pos="0 0 0" quat="1.0 0.0 0.0 0.0" material="urdf_visual" type="mesh" mesh="waist02.STL" class="visual" />
                <body name="waist03" pos="0 0 0.355" quat="1.0 0.0 0.0 0.0">
                  <joint name="LegWaist-5" type="hinge" ref="0.0" class="motor" range="-3.141592654 3.141592654" axis="0 0 1" />
                  <inertial pos="0.00888336 0.00326024 0.16681874" quat="1.0 0.0 0.0 0.0" mass="10.86382027" diaginertia="0.07787646 0.10789179 0.05721664" />
                  <geom name="waist03_collision" pos="0 0 -0.2531" quat="1.0 0.0 0.0 0.0" type="mesh" mesh="waist03.STL" class="collision" />
                  <geom name="waist03_visual" pos="0 0 -0.2531" quat="1.0 0.0 0.0 0.0" material="urdf_visual" type="mesh" mesh="waist03.STL" class="visual" />
                  <body name="left01" pos="0.1257 0 0" quat="1.0 0.0 0.0 0.0">
                    <joint name="LeftArm-0" type="hinge" ref="0.0" class="motor" range="-3.141592654 2.094395102" axis="1 0 0" />
                    <inertial pos="0.054749450000000005 0.00276998 0.00022292000000000001" quat="1.0 0.0 0.0 0.0" mass="2.2636205" diaginertia="0.002926269230241444 0.006088409913996264 0.005938954117902412" />
                    <geom name="left01_collision" pos="0 0 0" quat="1.0 0.0 0.0 0.0" type="mesh" mesh="left01.STL" class="collision" />
                    <geom name="left01_visual" pos="0 0 0" quat="1.0 0.0 0.0 0.0" material="urdf_visual" type="mesh" mesh="left01.STL" class="visual" />
                    <body name="left02" pos="0.079 0 0" quat="1.0 0.0 0.0 0.0">
                      <joint name="LeftArm-1" type="hinge" ref="0.0" class="motor" range="-2.967059728 0.157079633" axis="0 1 0" />
                      <inertial pos="-0.0007589000000000001 -0.008950010000000001 -0.059092799999999994" quat="1.0 0.0 0.0 0.0" mass="1.70151449" diaginertia="0.00996780527386167 0.008316431190972131 0.0036685141790974815" />
                      <geom name="left02_collision" pos="0 0 0" quat="1.0 0.0 0.0 0.0" type="mesh" mesh="left02.STL" class="collision" />
                      <geom name="left02_visual" pos="0 0 0" quat="1.0 0.0 0.0 0.0" material="urdf_visual" type="mesh" mesh="left02.STL" class="visual" />
                      <body name="left03" pos="0 0 -0.113" quat="1.0 0.0 0.0 0.0">
                        <joint name="LeftArm-2" type="hinge" ref="0.0" class="motor" range="-3.054326191 3.054326191" axis="0 0 1" />
                        <inertial pos="0.00354184 0.00051786 -0.12291618" quat="1.0 0.0 0.0 0.0" mass="2.16228797" diaginertia="0.012350936002402987 0.012533720778781045 0.0026359150160152668" />
                        <geom name="left03_collision" pos="0 0 0" quat="1.0 0.0 0.0 0.0" type="mesh" mesh="left03.STL" class="collision" />
                        <geom name="left03_visual" pos="0 0 0" quat="1.0 0.0 0.0 0.0" material="urdf_visual" type="mesh" mesh="left03.STL" class="visual" />
                        <body name="left04" pos="0 0 -0.187" quat="1.0 0.0 0.0 0.0">
                          <joint name="LeftArm-3" type="hinge" ref="0.0" class="motor" range="-2.251474735 0.174532925" axis="1 0 0" />
                          <inertial pos="-0.017389810000000002 7.621e-05 -0.05687889" quat="1.0 0.0 0.0 0.0" mass="1.06370626" diaginertia="0.004364892684267085 0.004516488247510417 0.0010309632073077905" />
                          <geom name="left04_collision" pos="0 0 0" quat="1.0 0.0 0.0 0.0" type="mesh" mesh="left04.STL" class="collision" />
                          <geom name="left04_visual" pos="0 0 0" quat="1.0 0.0 0.0 0.0" material="urdf_visual" type="mesh" mesh="left04.STL" class="visual" />
                          <body name="left05" pos="0 0 -0.101" quat="1.0 0.0 0.0 0.0">
                            <joint name="LeftArm-4" type="hinge" ref="0.0" class="motor" range="-3.054326191 3.054326191" axis="0 0 1" />
                            <inertial pos="0.00156708 -0.00511158 -0.09883365000000001" quat="1.0 0.0 0.0 0.0" mass="1.6289911" diaginertia="0.007388575032625348 0.007426497341332737 0.0017983369349761683" />
                            <geom name="left05_collision" pos="0 0 0" quat="1.0 0.0 0.0 0.0" type="mesh" mesh="left05.STL" class="collision" />
                            <geom name="left05_visual" pos="0 0 0" quat="1.0 0.0 0.0 0.0" material="urdf_visual" type="mesh" mesh="left05.STL" class="visual" />
                            <body name="left06" pos="0 0 -0.159" quat="1.0 0.0 0.0 0.0">
                              <joint name="LeftArm-5" type="hinge" ref="0.0" class="motor" range="-1.658062789 1.658062789" axis="0 1 0" />
                              <inertial pos="0.011664770000000001 0.01053484 -0.05012905" quat="1.0 0.0 0.0 0.0" mass="0.92138002" diaginertia="0.002565426812191393 0.002649844910861245 0.0008913533305148756" />
                              <geom name="left06_collision" pos="0 0 0" quat="1.0 0.0 0.0 0.0" type="mesh" mesh="left06.STL" class="collision" />
                              <geom name="left06_visual" pos="0 0 0" quat="1.0 0.0 0.0 0.0" material="urdf_visual" type="mesh" mesh="left06.STL" class="visual" />
                              <body name="left07" pos="0 0 -0.0905" quat="1.0 0.0 0.0 0.0">
                                <joint name="LeftArm-6" type="hinge" ref="0.0" class="motor" range="-1.570796327 1.570796327" axis="1 0 0" />
                                <inertial pos="-0.0050796999999999995 -3.6429999999999995e-05 -0.00136032" quat="1.0 0.0 0.0 0.0" mass="0.68822603" diaginertia="0.0007339455446568354 0.0007152579194629082 0.0006805805480547413" />
                                <geom name="left07_collision" pos="0 0 0" quat="1.0 0.0 0.0 0.0" type="mesh" mesh="left07.STL" class="collision" />
                                <geom name="left07_visual" pos="0 0 0" quat="1.0 0.0 0.0 0.0" material="urdf_visual" type="mesh" mesh="left07.STL" class="visual" />
                              </body>
                            </body>
                          </body>
                        </body>
                      </body>
                    </body>
                  </body>
                  <body name="right01" pos="-0.1257 0 0" quat="-1.0341155355510722e-13 -0.0 0.0 1.0">
                    <joint name="RightArm-0" type="hinge" ref="0.0" class="motor" range="-2.094395102 3.141592654" axis="1 0 0" />
                    <inertial pos="0.0547406 0.00275389 0.00021783" quat="1.0 0.0 0.0 0.0" mass="2.26440537" diaginertia="0.002928129507342756 0.006091016484625338 0.005943080883625134" />
                    <geom name="right01_collision" pos="0 0 0" quat="-1.0341155355510722e-13 0.0 -0.0 -1.0" type="mesh" mesh="right01.STL" class="collision" />
                    <geom name="right01_visual" pos="0 0 0" quat="-1.0341155355510722e-13 0.0 -0.0 -1.0" material="urdf_visual" type="mesh" mesh="right01.STL" class="visual" />
                    <body name="right02" pos="0.079 0 0" quat="1.0 0.0 0.0 0.0">
                      <joint name="RightArm-1" type="hinge" ref="0.0" class="motor" range="-2.967059728 0.157079633" axis="0 1 0" />
                      <inertial pos="-0.00080565 -0.008946609999999999 -0.05910909" quat="1.0 0.0 0.0 0.0" mass="1.70300256" diaginertia="0.00997433427479084 0.008320390345880332 0.003673103186619226" />
                      <geom name="right02_collision" pos="0 0 0" quat="-1.0341155355510722e-13 0.0 -0.0 -1.0" type="mesh" mesh="right02.STL" class="collision" />
                      <geom name="right02_visual" pos="0 0 0" quat="-1.0341155355510722e-13 0.0 -0.0 -1.0" material="urdf_visual" type="mesh" mesh="right02.STL" class="visual" />
                      <body name="right03" pos="0 0 -0.113" quat="1.0 0.0 0.0 0.0">
                        <joint name="RightArm-2" type="hinge" ref="0.0" class="motor" range="-3.054326191 3.054326191" axis="0 0 1" />
                        <inertial pos="0.00357305 -0.000532 -0.1229175" quat="1.0 0.0 0.0 0.0" mass="2.16234468" diaginertia="0.012351015408661417 0.012533401427894685 0.002635582028351848" />
                        <geom name="right03_collision" pos="0 0 0" quat="-1.0341155355510722e-13 0.0 -0.0 -1.0" type="mesh" mesh="right03.STL" class="collision" />
                        <geom name="right03_visual" pos="0 0 0" quat="-1.0341155355510722e-13 0.0 -0.0 -1.0" material="urdf_visual" type="mesh" mesh="right03.STL" class="visual" />
                        <body name="right04" pos="0 0 -0.187" quat="1.0 0.0 0.0 0.0">
                          <joint name="RightArm-3" type="hinge" ref="0.0" class="motor" range="-0.174532925 2.251474735" axis="1 0 0" />
                          <inertial pos="-0.01740539 6.063e-05 -0.05687889" quat="1.0 0.0 0.0 0.0" mass="1.06370626" diaginertia="0.004364894952053942 0.004515911602543754 0.0010303888301279843" />
                          <geom name="right04_collision" pos="0 0 0" quat="-1.0341155355510722e-13 0.0 -0.0 -1.0" type="mesh" mesh="right04.STL" class="collision" />
                          <geom name="right04_visual" pos="0 0 0" quat="-1.0341155355510722e-13 0.0 -0.0 -1.0" material="urdf_visual" type="mesh" mesh="right04.STL" class="visual" />
                          <body name="right05" pos="0 0 -0.101" quat="1.0 0.0 0.0 0.0">
                            <joint name="RightArm-4" type="hinge" ref="0.0" class="motor" range="-3.054326191 3.054326191" axis="0 0 1" />
                            <inertial pos="0.00161137 0.005111030000000001 -0.09883264" quat="1.0 0.0 0.0 0.0" mass="1.62900972" diaginertia="0.007388747043587482 0.007426461312592853 0.001798166240262274" />
                            <geom name="right05_collision" pos="0 0 0" quat="-1.0341155355510722e-13 0.0 -0.0 -1.0" type="mesh" mesh="right05.STL" class="collision" />
                            <geom name="right05_visual" pos="0 0 0" quat="-1.0341155355510722e-13 0.0 -0.0 -1.0" material="urdf_visual" type="mesh" mesh="right05.STL" class="visual" />
                            <body name="right06" pos="0 0 -0.159" quat="1.0 0.0 0.0 0.0">
                              <joint name="RightArm-5" type="hinge" ref="0.0" class="motor" range="-1.658062789 1.658062789" axis="0 1 0" />
                              <inertial pos="0.01160714 -0.010529120000000001 -0.050108849999999996" quat="1.0 0.0 0.0 0.0" mass="0.92044274" diaginertia="0.0025629807633314283 0.0026473859335554755 0.0008907202467415567" />
                              <geom name="right06_collision" pos="0 0 0" quat="-1.0341155355510722e-13 0.0 -0.0 -1.0" type="mesh" mesh="right06.STL" class="collision" />
                              <geom name="right06_visual" pos="0 0 0" quat="-1.0341155355510722e-13 0.0 -0.0 -1.0" material="urdf_visual" type="mesh" mesh="right06.STL" class="visual" />
                              <body name="right07" pos="0 0 -0.0905" quat="1.0 0.0 0.0 0.0">
                                <joint name="RightArm-6" type="hinge" ref="0.0" class="motor" range="-1.570796327 1.570796327" axis="1 0 0" />
                                <inertial pos="-0.005132520000000001 -4.9619999999999996e-05 -0.0013123" quat="1.0 0.0 0.0 0.0" mass="0.68915397" diaginertia="0.0007353514895880473 0.0007178789676814138 0.0006822440845001905" />
                                <geom name="right07_collision" pos="0 0 0" quat="-1.0341155355510722e-13 0.0 -0.0 -1.0" type="mesh" mesh="right07.STL" class="collision" />
                                <geom name="right07_visual" pos="0 0 0" quat="-1.0341155355510722e-13 0.0 -0.0 -1.0" material="urdf_visual" type="mesh" mesh="right07.STL" class="visual" />
                              </body>
                            </body>
                          </body>
                        </body>
                      </body>
                    </body>
                  </body>
                  <body name="head21" pos="0 0 0.096" quat="1.0 0.0 0.0 0.0">
                    <joint name="Head-0" type="hinge" ref="0.0" class="motor" range="-1.570796327 1.570796327" axis="0 0 1" />
                    <inertial pos="-0.0024550600000000002 0.010183999999999999 0.00271658" quat="1.0 0.0 0.0 0.0" mass="0.56836442" diaginertia="0.00020270831472221217 0.00022947986632296087 0.00016737702037794176" />
                    <geom name="head21_collision" pos="0 0 0" quat="1.0 0.0 0.0 0.0" type="mesh" mesh="head21.STL" class="collision" />
                    <geom name="head21_visual" pos="0 0 0" quat="1.0 0.0 0.0 0.0" material="urdf_visual" type="mesh" mesh="head21.STL" class="visual" />
                    <body name="head22" pos="0 0 0.103" quat="1.0 0.0 0.0 0.0">
                      <joint name="Head-1" type="hinge" ref="0.0" class="motor" range="-1.570796327 1.570796327" axis="1 0 0" />
                      <inertial pos="0.00787245 -1.155e-05 0.0024877099999999997" quat="1.0 0.0 0.0 0.0" mass="0.55596678" diaginertia="0.0001749492136407707 0.00017461298586781933 0.00014202362389233189" />
                      <geom name="head22_collision" pos="0 0 0" quat="1.0 0.0 0.0 0.0" type="mesh" mesh="head22.STL" class="collision" />
                      <geom name="head22_visual" pos="0 0 0" quat="1.0 0.0 0.0 0.0" material="urdf_visual" type="mesh" mesh="head22.STL" class="visual" />
                      <body name="head23" pos="0 0 0.04" quat="1.0 0.0 0.0 0.0">
                        <inertial pos="0.0015001 2.027e-05 0.03197392" quat="1.0 0.0 0.0 0.0" mass="0.55994701" diaginertia="0.0001400482695891373 0.00016536845089398658 0.00016662972117074569" />
                        <geom name="head23_collision" pos="0 0 0" quat="1.0 0.0 0.0 0.0" type="mesh" mesh="head23.STL" class="collision" />
                        <geom name="head23_visual" pos="0 0 0" quat="1.0 0.0 0.0 0.0" material="urdf_visual" type="mesh" mesh="head23.STL" class="visual" />
                        <body name="camera0_link" pos="0 -0.06195 0.0371" quat="1.0 0.0 0.0 0.0" />
                      </body>
                    </body>
                  </body>
                </body>
              </body>
            </body>
          </body>
        </body>
      </body>
      <site name="base_link_site" pos="0 0 0" quat="1 0 0 0" />
      <camera name="front_camera" mode="track" fovy="90.0" quat="4.329780281177467e-17 4.329780281177466e-17 0.7071067811865475 0.7071067811865476" pos="0.0 2.0 0.5" />
      <camera name="side_camera" mode="track" fovy="90.0" quat="-0.5 -0.4999999999999999 0.5 0.5000000000000001" pos="-2.0 0.0 0.5" />
    </body>
  </worldbody>

  <actuator>
    <motor name="Base-0_ctrl" joint="Base-0" class="motor" />
    <motor name="Base-1_ctrl" joint="Base-1" class="motor" />
    <motor name="Base-2_ctrl" joint="Base-2" class="motor" />
    <motor name="Base-3_ctrl" joint="Base-3" class="motor" />
    <motor name="LegWaist-0_ctrl" joint="LegWaist-0" class="motor" />
    <motor name="LegWaist-1_ctrl" joint="LegWaist-1" class="motor" />
    <motor name="LegWaist-2_ctrl" joint="LegWaist-2" class="motor" />
    <motor name="LegWaist-3_ctrl" joint="LegWaist-3" class="motor" />
    <motor name="LegWaist-4_ctrl" joint="LegWaist-4" class="motor" />
    <motor name="LegWaist-5_ctrl" joint="LegWaist-5" class="motor" />
    <motor name="LeftArm-0_ctrl" joint="LeftArm-0" class="motor" />
    <motor name="LeftArm-1_ctrl" joint="LeftArm-1" class="motor" />
    <motor name="LeftArm-2_ctrl" joint="LeftArm-2" class="motor" />
    <motor name="LeftArm-3_ctrl" joint="LeftArm-3" class="motor" />
    <motor name="LeftArm-4_ctrl" joint="LeftArm-4" class="motor" />
    <motor name="LeftArm-5_ctrl" joint="LeftArm-5" class="motor" />
    <motor name="LeftArm-6_ctrl" joint="LeftArm-6" class="motor" />
    <motor name="RightArm-0_ctrl" joint="RightArm-0" class="motor" />
    <motor name="RightArm-1_ctrl" joint="RightArm-1" class="motor" />
    <motor name="RightArm-2_ctrl" joint="RightArm-2" class="motor" />
    <motor name="RightArm-3_ctrl" joint="RightArm-3" class="motor" />
    <motor name="RightArm-4_ctrl" joint="RightArm-4" class="motor" />
    <motor name="RightArm-5_ctrl" joint="RightArm-5" class="motor" />
    <motor name="RightArm-6_ctrl" joint="RightArm-6" class="motor" />
    <motor name="Head-0_ctrl" joint="Head-0" class="motor" />
    <motor name="Head-1_ctrl" joint="Head-1" class="motor" />
  </actuator>

  <contact>
    <exclude body1="base_link" body2="wheel01" />
    <exclude body1="base_link" body2="wheel02" />
    <exclude body1="base_link" body2="wheel03" />
    <exclude body1="base_link" body2="wheel04" />
    <exclude body1="base_link" body2="lidar_link" />
    <exclude body1="base_link" body2="leg01" />
    <exclude body1="leg01" body2="leg02" />
    <exclude body1="leg02" body2="leg03" />
    <exclude body1="leg03" body2="waist01" />
    <exclude body1="waist01" body2="waist02" />
    <exclude body1="waist02" body2="waist03" />
    <exclude body1="waist03" body2="left01" />
    <exclude body1="left01" body2="left02" />
    <exclude body1="left02" body2="left03" />
    <exclude body1="left03" body2="left04" />
    <exclude body1="left04" body2="left05" />
    <exclude body1="left05" body2="left06" />
    <exclude body1="left06" body2="left07" />
    <exclude body1="waist03" body2="right01" />
    <exclude body1="right01" body2="right02" />
    <exclude body1="right02" body2="right03" />
    <exclude body1="right03" body2="right04" />
    <exclude body1="right04" body2="right05" />
    <exclude body1="right05" body2="right06" />
    <exclude body1="right06" body2="right07" />
    <exclude body1="waist03" body2="head21" />
    <exclude body1="head21" body2="head22" />
    <exclude body1="head22" body2="head23" />
  </contact>

  <!-- freejoint 下须用 qpos 抬高；nq=33（7 自由关节 + 26 铰链） -->
  <keyframe>
    <key
      name="stand"
      qpos="0 0 0.463 1 0 0 0 0 0 0 0 0 0 0 0 0 0 0 0 0 0 0 0 0 0 0 0 0 0 0 0 0 0"
    />
  </keyframe>

  <sensor>
    <framepos name="base_link_site_pos" objtype="site" objname="base_link_site" />
    <framequat name="base_link_site_quat" objtype="site" objname="base_link_site" />
    <framelinvel name="base_link_site_linvel" objtype="site" objname="base_link_site" />
    <frameangvel name="base_link_site_angvel" objtype="site" objname="base_link_site" />
    <velocimeter name="base_link_site_vel" site="base_link_site" />
  </sensor>
</mujoco>